{
    DataVersion: 3955,
    size: [3, 4, 3],
    data: [
        {pos: [0, 0, 0], state: "modern_industrialization:heatproof_machine_casing"},
        {pos: [0, 0, 1], state: "modern_industrialization:heatproof_machine_casing"},
        {pos: [0, 0, 2], state: "modern_industrialization:heatproof_machine_casing"},
        {pos: [1, 0, 0], state: "modern_industrialization:heatproof_machine_casing"},
        {pos: [1, 0, 1], state: "modern_industrialization:heatproof_machine_casing"},
        {pos: [1, 0, 2], state: "modern_industrialization:heatproof_machine_casing"},
        {pos: [2, 0, 0], state: "modern_industrialization:heatproof_machine_casing"},
        {pos: [2, 0, 1], state: "modern_industrialization:heatproof_machine_casing"},
        {pos: [2, 0, 2], state: "modern_industrialization:heatproof_machine_casing"},
        {pos: [0, 1, 0], state: "modern_industrialization:clean_stainless_steel_machine_casing"},
        {pos: [0, 1, 1], state: "modern_industrialization:clean_stainless_steel_machine_casing"},
        {pos: [0, 1, 2], state: "modern_industrialization:clean_stainless_steel_machine_casing"},
        {pos: [1, 1, 0], state: "modern_industrialization:high_pressure_large_steam_boiler", nbt: {burningEuBuffer: 0L, facingDirection: 2, id: "modern_industrialization:high_pressure_large_steam_boiler", placer: "f83bd929-fbf0-4186-becb-658d676fcc42", redstoneModuleStack: {}, silenced: 0b, steamBuffer: {}, temperature: 0.0d}},
        {pos: [1, 1, 1], state: "modern_industrialization:stainless_steel_machine_casing_pipe"},
        {pos: [1, 1, 2], state: "modern_industrialization:clean_stainless_steel_machine_casing"},
        {pos: [2, 1, 0], state: "modern_industrialization:clean_stainless_steel_machine_casing"},
        {pos: [2, 1, 1], state: "modern_industrialization:clean_stainless_steel_machine_casing"},
        {pos: [2, 1, 2], state: "modern_industrialization:clean_stainless_steel_machine_casing"},
        {pos: [0, 2, 0], state: "modern_industrialization:clean_stainless_steel_machine_casing"},
        {pos: [0, 2, 1], state: "modern_industrialization:clean_stainless_steel_machine_casing"},
        {pos: [0, 2, 2], state: "modern_industrialization:clean_stainless_steel_machine_casing"},
        {pos: [1, 2, 0], state: "modern_industrialization:clean_stainless_steel_machine_casing"},
        {pos: [1, 2, 1], state: "modern_industrialization:stainless_steel_machine_casing_pipe"},
        {pos: [1, 2, 2], state: "modern_industrialization:clean_stainless_steel_machine_casing"},
        {pos: [2, 2, 0], state: "modern_industrialization:clean_stainless_steel_machine_casing"},
        {pos: [2, 2, 1], state: "modern_industrialization:clean_stainless_steel_machine_casing"},
        {pos: [2, 2, 2], state: "modern_industrialization:clean_stainless_steel_machine_casing"},
        {pos: [0, 3, 0], state: "modern_industrialization:clean_stainless_steel_machine_casing"},
        {pos: [0, 3, 1], state: "modern_industrialization:clean_stainless_steel_machine_casing"},
        {pos: [0, 3, 2], state: "modern_industrialization:clean_stainless_steel_machine_casing"},
        {pos: [1, 3, 0], state: "modern_industrialization:clean_stainless_steel_machine_casing"},
        {pos: [1, 3, 1], state: "modern_industrialization:clean_stainless_steel_machine_casing"},
        {pos: [1, 3, 2], state: "modern_industrialization:clean_stainless_steel_machine_casing"},
        {pos: [2, 3, 0], state: "modern_industrialization:clean_stainless_steel_machine_casing"},
        {pos: [2, 3, 1], state: "modern_industrialization:clean_stainless_steel_machine_casing"},
        {pos: [2, 3, 2], state: "modern_industrialization:clean_stainless_steel_machine_casing"}
    ],
    entities: [],
    palette: [
        "modern_industrialization:heatproof_machine_casing",
        "modern_industrialization:clean_stainless_steel_machine_casing",
        "modern_industrialization:stainless_steel_machine_casing_pipe",
        "modern_industrialization:high_pressure_large_steam_boiler"
    ]
}