{
    DataVersion: 3955,
    size: [3, 3, 4],
    data: [
        {pos: [0, 0, 0], state: "modern_industrialization:clean_stainless_steel_machine_casing"},
        {pos: [0, 0, 1], state: "modern_industrialization:stainless_steel_machine_casing_pipe"},
        {pos: [0, 0, 2], state: "modern_industrialization:stainless_steel_machine_casing_pipe"},
        {pos: [0, 0, 3], state: "modern_industrialization:clean_stainless_steel_machine_casing"},
        {pos: [1, 0, 0], state: "modern_industrialization:clean_stainless_steel_machine_casing"},
        {pos: [1, 0, 1], state: "modern_industrialization:stainless_steel_machine_casing_pipe"},
        {pos: [1, 0, 2], state: "modern_industrialization:stainless_steel_machine_casing_pipe"},
        {pos: [1, 0, 3], state: "modern_industrialization:clean_stainless_steel_machine_casing"},
        {pos: [2, 0, 0], state: "modern_industrialization:clean_stainless_steel_machine_casing"},
        {pos: [2, 0, 1], state: "modern_industrialization:stainless_steel_machine_casing_pipe"},
        {pos: [2, 0, 2], state: "modern_industrialization:stainless_steel_machine_casing_pipe"},
        {pos: [2, 0, 3], state: "modern_industrialization:clean_stainless_steel_machine_casing"},
        {pos: [0, 1, 0], state: "modern_industrialization:clean_stainless_steel_machine_casing"},
        {pos: [0, 1, 1], state: "modern_industrialization:stainless_steel_machine_casing_pipe"},
        {pos: [0, 1, 2], state: "modern_industrialization:stainless_steel_machine_casing_pipe"},
        {pos: [0, 1, 3], state: "modern_industrialization:clean_stainless_steel_machine_casing"},
        {pos: [1, 1, 0], state: "modern_industrialization:large_steam_turbine", nbt: {activeShape: 0, euBuffer: 0L, facingDirection: 2, id: "modern_industrialization:large_steam_turbine", placer: "f83bd929-fbf0-4186-becb-658d676fcc42", redstoneModuleStack: {}, silenced: 0b}},
        {pos: [1, 1, 1], state: "modern_industrialization:stainless_steel_machine_casing_pipe"},
        {pos: [1, 1, 2], state: "modern_industrialization:stainless_steel_machine_casing_pipe"},
        {pos: [1, 1, 3], state: "modern_industrialization:clean_stainless_steel_machine_casing"},
        {pos: [2, 1, 0], state: "modern_industrialization:clean_stainless_steel_machine_casing"},
        {pos: [2, 1, 1], state: "modern_industrialization:stainless_steel_machine_casing_pipe"},
        {pos: [2, 1, 2], state: "modern_industrialization:stainless_steel_machine_casing_pipe"},
        {pos: [2, 1, 3], state: "modern_industrialization:clean_stainless_steel_machine_casing"},
        {pos: [0, 2, 0], state: "modern_industrialization:clean_stainless_steel_machine_casing"},
        {pos: [0, 2, 1], state: "modern_industrialization:stainless_steel_machine_casing_pipe"},
        {pos: [0, 2, 2], state: "modern_industrialization:stainless_steel_machine_casing_pipe"},
        {pos: [0, 2, 3], state: "modern_industrialization:clean_stainless_steel_machine_casing"},
        {pos: [1, 2, 0], state: "modern_industrialization:clean_stainless_steel_machine_casing"},
        {pos: [1, 2, 1], state: "modern_industrialization:stainless_steel_machine_casing_pipe"},
        {pos: [1, 2, 2], state: "modern_industrialization:stainless_steel_machine_casing_pipe"},
        {pos: [1, 2, 3], state: "modern_industrialization:clean_stainless_steel_machine_casing"},
        {pos: [2, 2, 0], state: "modern_industrialization:clean_stainless_steel_machine_casing"},
        {pos: [2, 2, 1], state: "modern_industrialization:stainless_steel_machine_casing_pipe"},
        {pos: [2, 2, 2], state: "modern_industrialization:stainless_steel_machine_casing_pipe"},
        {pos: [2, 2, 3], state: "modern_industrialization:clean_stainless_steel_machine_casing"}
    ],
    entities: [],
    palette: [
        "modern_industrialization:clean_stainless_steel_machine_casing",
        "modern_industrialization:stainless_steel_machine_casing_pipe",
        "modern_industrialization:large_steam_turbine"
    ]
}