{
    DataVersion: 3955,
    size: [5, 4, 4],
    data: [
        {pos: [0, 0, 0], state: "modern_industrialization:steel_machine_casing"},
        {pos: [0, 0, 1], state: "modern_industrialization:steel_machine_casing"},
        {pos: [0, 0, 2], state: "modern_industrialization:steel_machine_casing"},
        {pos: [0, 0, 3], state: "modern_industrialization:steel_machine_casing"},
        {pos: [1, 0, 0], state: "modern_industrialization:steel_machine_casing"},
        {pos: [1, 0, 1], state: "minecraft:glass"},
        {pos: [1, 0, 2], state: "minecraft:glass"},
        {pos: [1, 0, 3], state: "modern_industrialization:steel_machine_casing"},
        {pos: [2, 0, 0], state: "modern_industrialization:steel_machine_casing"},
        {pos: [2, 0, 1], state: "minecraft:glass"},
        {pos: [2, 0, 2], state: "minecraft:glass"},
        {pos: [2, 0, 3], state: "modern_industrialization:steel_machine_casing"},
        {pos: [3, 0, 0], state: "modern_industrialization:steel_machine_casing"},
        {pos: [3, 0, 1], state: "minecraft:glass"},
        {pos: [3, 0, 2], state: "minecraft:glass"},
        {pos: [3, 0, 3], state: "modern_industrialization:steel_machine_casing"},
        {pos: [4, 0, 0], state: "modern_industrialization:steel_machine_casing"},
        {pos: [4, 0, 1], state: "modern_industrialization:steel_machine_casing"},
        {pos: [4, 0, 2], state: "modern_industrialization:steel_machine_casing"},
        {pos: [4, 0, 3], state: "modern_industrialization:steel_machine_casing"},
        {pos: [0, 1, 0], state: "modern_industrialization:steel_machine_casing"},
        {pos: [0, 1, 1], state: "minecraft:glass"},
        {pos: [0, 1, 2], state: "minecraft:glass"},
        {pos: [0, 1, 3], state: "modern_industrialization:steel_machine_casing"},
        {pos: [1, 1, 0], state: "minecraft:glass"},
        {pos: [1, 1, 3], state: "minecraft:glass"},
        {pos: [2, 1, 0], state: "modern_industrialization:large_tank", nbt: {activeShape: 31, amount: 0L, capacity: 5120000L, facingDirection: 2, fluid: {}, id: "modern_industrialization:large_tank", placer: "f83bd929-fbf0-4186-becb-658d676fcc42", silenced: 0b}},
        {pos: [2, 1, 3], state: "minecraft:glass"},
        {pos: [3, 1, 0], state: "minecraft:glass"},
        {pos: [3, 1, 3], state: "minecraft:glass"},
        {pos: [4, 1, 0], state: "modern_industrialization:steel_machine_casing"},
        {pos: [4, 1, 1], state: "minecraft:glass"},
        {pos: [4, 1, 2], state: "minecraft:glass"},
        {pos: [4, 1, 3], state: "modern_industrialization:steel_machine_casing"},
        {pos: [0, 2, 0], state: "modern_industrialization:steel_machine_casing"},
        {pos: [0, 2, 1], state: "minecraft:glass"},
        {pos: [0, 2, 2], state: "minecraft:glass"},
        {pos: [0, 2, 3], state: "modern_industrialization:steel_machine_casing"},
        {pos: [1, 2, 0], state: "minecraft:glass"},
        {pos: [1, 2, 3], state: "minecraft:glass"},
        {pos: [2, 2, 0], state: "minecraft:glass"},
        {pos: [2, 2, 3], state: "minecraft:glass"},
        {pos: [3, 2, 0], state: "minecraft:glass"},
        {pos: [3, 2, 3], state: "minecraft:glass"},
        {pos: [4, 2, 0], state: "modern_industrialization:steel_machine_casing"},
        {pos: [4, 2, 1], state: "minecraft:glass"},
        {pos: [4, 2, 2], state: "minecraft:glass"},
        {pos: [4, 2, 3], state: "modern_industrialization:steel_machine_casing"},
        {pos: [0, 3, 0], state: "modern_industrialization:steel_machine_casing"},
        {pos: [0, 3, 1], state: "modern_industrialization:steel_machine_casing"},
        {pos: [0, 3, 2], state: "modern_industrialization:steel_machine_casing"},
        {pos: [0, 3, 3], state: "modern_industrialization:steel_machine_casing"},
        {pos: [1, 3, 0], state: "modern_industrialization:steel_machine_casing"},
        {pos: [1, 3, 1], state: "minecraft:glass"},
        {pos: [1, 3, 2], state: "minecraft:glass"},
        {pos: [1, 3, 3], state: "modern_industrialization:steel_machine_casing"},
        {pos: [2, 3, 0], state: "modern_industrialization:steel_machine_casing"},
        {pos: [2, 3, 1], state: "minecraft:glass"},
        {pos: [2, 3, 2], state: "minecraft:glass"},
        {pos: [2, 3, 3], state: "modern_industrialization:steel_machine_casing"},
        {pos: [3, 3, 0], state: "modern_industrialization:steel_machine_casing"},
        {pos: [3, 3, 1], state: "minecraft:glass"},
        {pos: [3, 3, 2], state: "minecraft:glass"},
        {pos: [3, 3, 3], state: "modern_industrialization:steel_machine_casing"},
        {pos: [4, 3, 0], state: "modern_industrialization:steel_machine_casing"},
        {pos: [4, 3, 1], state: "modern_industrialization:steel_machine_casing"},
        {pos: [4, 3, 2], state: "modern_industrialization:steel_machine_casing"},
        {pos: [4, 3, 3], state: "modern_industrialization:steel_machine_casing"}
    ],
    entities: [],
    palette: [
        "modern_industrialization:steel_machine_casing",
        "minecraft:glass",
        "modern_industrialization:large_tank"
    ]
}