{
    DataVersion: 3955,
    size: [5, 10, 5],
    data: [
        {pos: [0, 0, 0], state: "modern_industrialization:steel_machine_casing"},
        {pos: [0, 0, 4], state: "modern_industrialization:steel_machine_casing"},
        {pos: [1, 0, 2], state: "minecraft:chain{axis:y,waterlogged:false}"},
        {pos: [3, 0, 2], state: "minecraft:chain{axis:y,waterlogged:false}"},
        {pos: [4, 0, 0], state: "modern_industrialization:steel_machine_casing"},
        {pos: [4, 0, 4], state: "modern_industrialization:steel_machine_casing"},
        {pos: [0, 1, 0], state: "modern_industrialization:steel_machine_casing"},
        {pos: [0, 1, 4], state: "modern_industrialization:steel_machine_casing"},
        {pos: [1, 1, 2], state: "minecraft:chain{axis:y,waterlogged:false}"},
        {pos: [3, 1, 2], state: "minecraft:chain{axis:y,waterlogged:false}"},
        {pos: [4, 1, 0], state: "modern_industrialization:steel_machine_casing"},
        {pos: [4, 1, 4], state: "modern_industrialization:steel_machine_casing"},
        {pos: [0, 2, 0], state: "modern_industrialization:steel_machine_casing"},
        {pos: [0, 2, 4], state: "modern_industrialization:steel_machine_casing"},
        {pos: [1, 2, 2], state: "minecraft:chain{axis:y,waterlogged:false}"},
        {pos: [3, 2, 2], state: "minecraft:chain{axis:y,waterlogged:false}"},
        {pos: [4, 2, 0], state: "modern_industrialization:steel_machine_casing"},
        {pos: [4, 2, 4], state: "modern_industrialization:steel_machine_casing"},
        {pos: [0, 3, 0], state: "modern_industrialization:steel_machine_casing"},
        {pos: [0, 3, 1], state: "modern_industrialization:steel_machine_casing"},
        {pos: [0, 3, 2], state: "modern_industrialization:steel_machine_casing"},
        {pos: [0, 3, 3], state: "modern_industrialization:steel_machine_casing"},
        {pos: [0, 3, 4], state: "modern_industrialization:steel_machine_casing"},
        {pos: [1, 3, 0], state: "modern_industrialization:steel_machine_casing"},
        {pos: [1, 3, 2], state: "minecraft:chain{axis:y,waterlogged:false}"},
        {pos: [1, 3, 4], state: "modern_industrialization:steel_machine_casing"},
        {pos: [2, 3, 0], state: "modern_industrialization:steel_machine_casing"},
        {pos: [2, 3, 2], state: "modern_industrialization:steel_machine_casing_pipe"},
        {pos: [2, 3, 4], state: "modern_industrialization:steel_machine_casing"},
        {pos: [3, 3, 0], state: "modern_industrialization:steel_machine_casing"},
        {pos: [3, 3, 2], state: "minecraft:chain{axis:y,waterlogged:false}"},
        {pos: [3, 3, 4], state: "modern_industrialization:steel_machine_casing"},
        {pos: [4, 3, 0], state: "modern_industrialization:steel_machine_casing"},
        {pos: [4, 3, 1], state: "modern_industrialization:steel_machine_casing"},
        {pos: [4, 3, 2], state: "modern_industrialization:steel_machine_casing"},
        {pos: [4, 3, 3], state: "modern_industrialization:steel_machine_casing"},
        {pos: [4, 3, 4], state: "modern_industrialization:steel_machine_casing"},
        {pos: [1, 4, 1], state: "modern_industrialization:steel_machine_casing"},
        {pos: [1, 4, 2], state: "minecraft:chain{axis:y,waterlogged:false}"},
        {pos: [1, 4, 3], state: "modern_industrialization:steel_machine_casing"},
        {pos: [2, 4, 1], state: "modern_industrialization:oil_drilling_rig", nbt: {activeShape: 0, efficiencyTicks: 0, facingDirection: 2, id: "modern_industrialization:oil_drilling_rig", maxEfficiencyTicks: 0, overdriveModuleStack: {}, placer: "f83bd929-fbf0-4186-becb-658d676fcc42", recipeEnergy: 0L, recipeMaxEu: 0L, redstoneModuleStack: {}, upgradesItemStack: {}, usedEnergy: 0L}},
        {pos: [2, 4, 2], state: "modern_industrialization:steel_machine_casing_pipe"},
        {pos: [2, 4, 3], state: "modern_industrialization:steel_machine_casing"},
        {pos: [3, 4, 1], state: "modern_industrialization:steel_machine_casing"},
        {pos: [3, 4, 2], state: "minecraft:chain{axis:y,waterlogged:false}"},
        {pos: [3, 4, 3], state: "modern_industrialization:steel_machine_casing"},
        {pos: [1, 5, 2], state: "minecraft:chain{axis:y,waterlogged:false}"},
        {pos: [2, 5, 2], state: "modern_industrialization:steel_machine_casing_pipe"},
        {pos: [3, 5, 2], state: "minecraft:chain{axis:y,waterlogged:false}"},
        {pos: [1, 6, 2], state: "minecraft:chain{axis:y,waterlogged:false}"},
        {pos: [2, 6, 2], state: "modern_industrialization:steel_machine_casing_pipe"},
        {pos: [3, 6, 2], state: "minecraft:chain{axis:y,waterlogged:false}"},
        {pos: [1, 7, 2], state: "minecraft:chain{axis:y,waterlogged:false}"},
        {pos: [2, 7, 2], state: "modern_industrialization:steel_machine_casing_pipe"},
        {pos: [3, 7, 2], state: "minecraft:chain{axis:y,waterlogged:false}"},
        {pos: [1, 8, 2], state: "minecraft:chain{axis:y,waterlogged:false}"},
        {pos: [2, 8, 2], state: "modern_industrialization:steel_machine_casing_pipe"},
        {pos: [3, 8, 2], state: "minecraft:chain{axis:y,waterlogged:false}"},
        {pos: [0, 9, 2], state: "modern_industrialization:steel_machine_casing"},
        {pos: [1, 9, 2], state: "modern_industrialization:steel_machine_casing"},
        {pos: [2, 9, 2], state: "modern_industrialization:steel_machine_casing"},
        {pos: [3, 9, 2], state: "modern_industrialization:steel_machine_casing"},
        {pos: [4, 9, 2], state: "modern_industrialization:steel_machine_casing"}
    ],
    entities: [],
    palette: [
        "modern_industrialization:steel_machine_casing",
        "modern_industrialization:steel_machine_casing_pipe",
        "minecraft:chain{axis:y,waterlogged:false}",
        "modern_industrialization:oil_drilling_rig"
    ]
}