{
    DataVersion: 3955,
    size: [3, 4, 3],
    data: [
        {pos: [0, 0, 0], state: "modern_industrialization:fire_clay_bricks"},
        {pos: [0, 0, 1], state: "modern_industrialization:fire_clay_bricks"},
        {pos: [0, 0, 2], state: "modern_industrialization:fire_clay_bricks"},
        {pos: [1, 0, 0], state: "modern_industrialization:fire_clay_bricks"},
        {pos: [1, 0, 1], state: "modern_industrialization:fire_clay_bricks"},
        {pos: [1, 0, 2], state: "modern_industrialization:fire_clay_bricks"},
        {pos: [2, 0, 0], state: "modern_industrialization:fire_clay_bricks"},
        {pos: [2, 0, 1], state: "modern_industrialization:fire_clay_bricks"},
        {pos: [2, 0, 2], state: "modern_industrialization:fire_clay_bricks"},
        {pos: [0, 1, 0], state: "modern_industrialization:fire_clay_bricks"},
        {pos: [0, 1, 1], state: "modern_industrialization:fire_clay_bricks"},
        {pos: [0, 1, 2], state: "modern_industrialization:fire_clay_bricks"},
        {pos: [1, 1, 0], state: "modern_industrialization:steam_blast_furnace", nbt: {activeShape: 0, efficiencyTicks: 0, facingDirection: 2, id: "modern_industrialization:steam_blast_furnace", maxEfficiencyTicks: 0, placer: "f83bd929-fbf0-4186-becb-658d676fcc42", recipeEnergy: 0L, recipeMaxEu: 0L, silenced: 0b, usedEnergy: 0L}},
        {pos: [1, 1, 1], state: "minecraft:light{level:15,waterlogged:false}"},
        {pos: [1, 1, 2], state: "modern_industrialization:fire_clay_bricks"},
        {pos: [2, 1, 0], state: "modern_industrialization:fire_clay_bricks"},
        {pos: [2, 1, 1], state: "modern_industrialization:fire_clay_bricks"},
        {pos: [2, 1, 2], state: "modern_industrialization:fire_clay_bricks"},
        {pos: [0, 2, 0], state: "modern_industrialization:fire_clay_bricks"},
        {pos: [0, 2, 1], state: "modern_industrialization:fire_clay_bricks"},
        {pos: [0, 2, 2], state: "modern_industrialization:fire_clay_bricks"},
        {pos: [1, 2, 0], state: "modern_industrialization:fire_clay_bricks"},
        {pos: [1, 2, 1], state: "minecraft:light{level:15,waterlogged:false}"},
        {pos: [1, 2, 2], state: "modern_industrialization:fire_clay_bricks"},
        {pos: [2, 2, 0], state: "modern_industrialization:fire_clay_bricks"},
        {pos: [2, 2, 1], state: "modern_industrialization:fire_clay_bricks"},
        {pos: [2, 2, 2], state: "modern_industrialization:fire_clay_bricks"},
        {pos: [0, 3, 0], state: "modern_industrialization:fire_clay_bricks"},
        {pos: [0, 3, 1], state: "modern_industrialization:fire_clay_bricks"},
        {pos: [0, 3, 2], state: "modern_industrialization:fire_clay_bricks"},
        {pos: [1, 3, 0], state: "modern_industrialization:fire_clay_bricks"},
        {pos: [1, 3, 2], state: "modern_industrialization:fire_clay_bricks"},
        {pos: [2, 3, 0], state: "modern_industrialization:fire_clay_bricks"},
        {pos: [2, 3, 1], state: "modern_industrialization:fire_clay_bricks"},
        {pos: [2, 3, 2], state: "modern_industrialization:fire_clay_bricks"}
    ],
    entities: [],
    palette: [
        "modern_industrialization:fire_clay_bricks",
        "minecraft:light{level:15,waterlogged:false}",
        "modern_industrialization:steam_blast_furnace"
    ]
}